<?xml version="1.0" ?>
<!-- =================================================================================== -->
<!-- |    This document was autogenerated by xacro from iiwa14.urdf.xacro              | -->
<!-- |    EDITING THIS FILE BY HAND IS NOT RECOMMENDED                                 | -->
<!-- =================================================================================== -->
<!-- 
    Generated with 'rosrun xacro xacro \-\-inorder -o model.urdf iiwa14.urdf.xacro'.
    iiwa14.urdf.xacro from https://github.com/kuka-isir/iiwa_description/tree/master, commit 8062a47
 -->
<robot name="iiwa14">

  <klampt use_vis_geom="1"/>

  <!-- Fix to world just for testing -->
  <link name="world"/>
  <!--joint between {parent} and link_0-->
  <joint name="world_joint" type="fixed">
    <origin rpy="0 0 0" xyz="0 0 0.0"/>
    <parent link="world"/>
    <child link="link_0"/>
  </joint>
  <link name="link_0">
    <inertial>
      <origin rpy="0 0 0" xyz="-0.1 0 0.07"/>
      <mass value="5"/>
      <inertia ixx="0.05" ixy="0" ixz="0" iyy="0.06" iyz="0" izz="0.03"/>
    </inertial>
    <visual>
      <origin rpy="0 0 0" xyz="0 0 0"/>
      <geometry>
        <mesh filename="urdfs/iiwa14/meshes/visual/link_0.stl"/>
      </geometry>
      <material name="Grey"><color rgba="0.4 0.4 0.4 1.0"/></material>
    </visual>
    <collision>
      <origin rpy="0 0 0" xyz="0 0 0"/>
      <geometry>
        <mesh filename="urdfs/iiwa14/meshes/collision/link_0_s.stl"/>
      </geometry>
      <material name="Grey"><color rgba="0.4 0.4 0.4 1.0"/></material>
    </collision>
    <self_collision_checking>
      <origin rpy="0 0 0" xyz="0 0 0"/>
      <geometry>
        <capsule length="0.25" radius="0.15"/>
      </geometry>
    </self_collision_checking>
  </link>
  <!-- joint between link_0 and link_1 -->
  <joint name="joint_0" type="revolute">
    <parent link="link_0"/>
    <child link="link_1"/>
    <origin rpy="0 0 0" xyz="0 0 0.1575"/>
    <axis xyz="0 0 1"/>
    <limit effort="300" lower="-2.9670597283903604" upper="2.9670597283903604" velocity="10"/>
    <safety_controller k_position="100" k_velocity="2" soft_lower_limit="-2.9321531433504737" soft_upper_limit="2.9321531433504737"/>
    <dynamics damping="0.0" friction="0.0"/>
  </joint>

  <link name="link_1">
    <inertial>
      <origin rpy="0 0 0" xyz="0 -0.03 0.12"/>
      <mass value="4"/>
      <inertia ixx="0.1" ixy="0" ixz="0" iyy="0.09" iyz="0" izz="0.02"/>
    </inertial>
    <visual>
      <origin rpy="0 0 0" xyz="0 0 0"/>
      <geometry>
        <mesh filename="urdfs/iiwa14/meshes/visual/link_1.stl"/>
      </geometry>
      <material name="Orange"><color rgba="1.0 0.4235294117647059 0.0392156862745098 1.0"/></material>
    </visual>
    <collision>
      <origin rpy="0 0 0" xyz="0 0 0"/>
      <geometry>
        <mesh filename="urdfs/iiwa14/meshes/collision/link_1_s.stl"/>
      </geometry>
      <material name="Orange"><color rgba="1.0 0.4235294117647059 0.0392156862745098 1.0"/></material>
    </collision>
  </link>

  <!-- joint between link_1 and link_2 -->
  <joint name="joint_1" type="revolute">
    <parent link="link_1"/>
    <child link="link_2"/>
    <origin rpy="1.5707963267948966   0 3.141592653589793" xyz="0 0 0.2025"/>
    <axis xyz="0 0 1"/>
    <limit effort="300" lower="-2.0943951023931953" upper="2.0943951023931953" velocity="10"/>
    <safety_controller k_position="100" k_velocity="2" soft_lower_limit="-2.0594885173533086" soft_upper_limit="2.0594885173533086"/>
    <dynamics damping="0.0" friction="0.0"/>
  </joint>
  <link name="link_2">
    <inertial>
      <origin rpy="0 0 0" xyz="0.0003 0.059 0.042"/>
      <mass value="4"/>
      <inertia ixx="0.05" ixy="0" ixz="0" iyy="0.018" iyz="0" izz="0.044"/>
    </inertial>
    <visual>
      <origin rpy="0 0 0" xyz="0 0 0"/>
      <geometry>
        <mesh filename="urdfs/iiwa14/meshes/visual/link_2.stl"/>
      </geometry>
      <material name="Orange"><color rgba="1.0 0.4235294117647059 0.0392156862745098 1.0"/></material>
    </visual>
    <collision>
      <origin rpy="0 0 0" xyz="0 0 0"/>
      <geometry>
        <mesh filename="urdfs/iiwa14/meshes/collision/link_2_s.stl"/>
      </geometry>
      <material name="Orange"><color rgba="1.0 0.4235294117647059 0.0392156862745098 1.0"/></material>
    </collision>
  </link>
  <!-- joint between link_2 and link_3 -->
  <joint name="joint_2" type="revolute">
    <parent link="link_2"/>
    <child link="link_3"/>
    <origin rpy="1.5707963267948966 0 3.141592653589793" xyz="0 0.2045 0"/>
    <axis xyz="0 0 1"/>
    <limit effort="300" lower="-2.9670597283903604" upper="2.9670597283903604" velocity="10"/>
    <safety_controller k_position="100" k_velocity="2" soft_lower_limit="-2.9321531433504737" soft_upper_limit="2.9321531433504737"/>
    <dynamics damping="0.0" friction="0.0"/>
  </joint>
  <link name="link_3">
    <inertial>
      <origin rpy="0 0 0" xyz="0 0.03 0.13"/>
      <mass value="3"/>
      <inertia ixx="0.08" ixy="0" ixz="0" iyy="0.075" iyz="0" izz="0.01"/>
    </inertial>
    <visual>
      <origin rpy="0 0 0" xyz="0 0 0"/>
      <geometry>
        <mesh filename="urdfs/iiwa14/meshes/visual/link_3.stl"/>
      </geometry>
      <material name="Orange"><color rgba="1.0 0.4235294117647059 0.0392156862745098 1.0"/></material>
    </visual>
    <collision>
      <origin rpy="0 0 0" xyz="0 0 0"/>
      <geometry>
        <mesh filename="urdfs/iiwa14/meshes/collision/link_3_s.stl"/>
      </geometry>
      <material name="Orange"><color rgba="1.0 0.4235294117647059 0.0392156862745098 1.0"/></material>
    </collision>
  </link>
  <!-- joint between link_3 and link_4 -->
  <joint name="joint_3" type="revolute">
    <parent link="link_3"/>
    <child link="link_4"/>
    <origin rpy="1.5707963267948966 0 0" xyz="0 0 0.2155"/>
    <axis xyz="0 0 1"/>
    <limit effort="300" lower="-2.0943951023931953" upper="2.0943951023931953" velocity="10"/>
    <safety_controller k_position="100" k_velocity="2" soft_lower_limit="-2.0594885173533086" soft_upper_limit="2.0594885173533086"/>
    <dynamics damping="0.0" friction="0.0"/>
  </joint>
  <link name="link_4">
    <inertial>
      <origin rpy="0 0 0" xyz="0 0.067 0.034"/>
      <mass value="2.7"/>
      <inertia ixx="0.03" ixy="0" ixz="0" iyy="0.01" iyz="0" izz="0.029"/>
    </inertial>
    <visual>
      <origin rpy="0 0 0" xyz="0 0 0"/>
      <geometry>
        <mesh filename="urdfs/iiwa14/meshes/visual/link_4.stl"/>
      </geometry>
      <material name="Orange"><color rgba="1.0 0.4235294117647059 0.0392156862745098 1.0"/></material>
    </visual>
    <collision>
      <origin rpy="0 0 0" xyz="0 0 0"/>
      <geometry>
        <mesh filename="urdfs/iiwa14/meshes/collision/link_4_s.stl"/>
      </geometry>
      <material name="Orange"><color rgba="1.0 0.4235294117647059 0.0392156862745098 1.0"/></material>
    </collision>
  </link>
  <!-- joint between link_4 and link_5 -->
  <joint name="joint_4" type="revolute">
    <parent link="link_4"/>
    <child link="link_5"/>
    <origin rpy="-1.5707963267948966 3.141592653589793 0" xyz="0 0.1845 0"/>
    <axis xyz="0 0 1"/>
    <limit effort="300" lower="-2.9670597283903604" upper="2.9670597283903604" velocity="10"/>
    <safety_controller k_position="100" k_velocity="2" soft_lower_limit="-2.9321531433504737" soft_upper_limit="2.9321531433504737"/>
    <dynamics damping="0.0" friction="0.0"/>
  </joint>
  <link name="link_5">
    <inertial>
      <origin rpy="0 0 0" xyz="0.0001 0.021 0.076"/>
      <mass value="1.7"/>
      <inertia ixx="0.02" ixy="0" ixz="0" iyy="0.018" iyz="0" izz="0.005"/>
    </inertial>
    <visual>
      <origin rpy="0 0 0" xyz="0 0 0"/>
      <geometry>
        <mesh filename="urdfs/iiwa14/meshes/visual/link_5.stl"/>
      </geometry>
      <material name="Orange"><color rgba="1.0 0.4235294117647059 0.0392156862745098 1.0"/></material>
    </visual>
    <collision>
      <origin rpy="0 0 0" xyz="0 0 0"/>
      <geometry>
        <mesh filename="urdfs/iiwa14/meshes/collision/link_5_s.stl"/>
      </geometry>
      <material name="Orange"><color rgba="1.0 0.4235294117647059 0.0392156862745098 1.0"/></material>
    </collision>
  </link>
  <!-- joint between link_5 and link_6 -->
  <joint name="joint_5" type="revolute">
    <parent link="link_5"/>
    <child link="link_6"/>
    <origin rpy="1.5707963267948966 0 0" xyz="0 0 0.2155"/>
    <axis xyz="0 0 1"/>
    <limit effort="300" lower="-2.0943951023931953" upper="2.0943951023931953" velocity="10"/>
    <safety_controller k_position="100" k_velocity="2" soft_lower_limit="-2.0594885173533086" soft_upper_limit="2.0594885173533086"/>
    <dynamics damping="0.0" friction="0.0"/>
  </joint>
  <link name="link_6">
    <inertial>
      <origin rpy="0 0 0" xyz="0 0.0006 0.0004"/>
      <mass value="1.8"/>
      <inertia ixx="0.025" ixy="0" ixz="0" iyy="0.0136" iyz="0" izz="0.0247"/>
    </inertial>
    <visual>
      <origin rpy="0 0 0" xyz="0 0 0"/>
      <geometry>
        <mesh filename="urdfs/iiwa14/meshes/visual/link_6.stl"/>
      </geometry>
      <material name="Orange"><color rgba="1.0 0.4235294117647059 0.0392156862745098 1.0"/></material>
    </visual>
    <collision>
      <origin rpy="0 0 0" xyz="0 0 0"/>
      <geometry>
        <mesh filename="urdfs/iiwa14/meshes/collision/link_6_s.stl"/>
      </geometry>
      <material name="Orange"><color rgba="1.0 0.4235294117647059 0.0392156862745098 1.0"/></material>
    </collision>
  </link>
  <!-- joint between link_6 and link_7 -->
  <joint name="joint_6" type="revolute">
    <parent link="link_6"/>
    <child link="link_7"/>
    <origin rpy="-1.5707963267948966 3.141592653589793 0" xyz="0 0.081 0"/>
    <axis xyz="0 0 1"/>
    <limit effort="300" lower="-3.0543261909900763" upper="3.0543261909900763" velocity="10"/>
    <safety_controller k_position="100" k_velocity="2" soft_lower_limit="-3.01941960595019" soft_upper_limit="3.01941960595019"/>
    <dynamics damping="0.0" friction="0.0"/>
  </joint>

  <link name="link_7">
    <inertial>
      <origin rpy="0 0 0" xyz="0 0 0.02"/>
      <mass value="0.42857142857142855"/>
      <!--this is for the MFT Pneumatisch flange-->
      <inertia ixx="0.01" ixy="0" ixz="0" iyy="0.01" iyz="0" izz="0.01"/>
    </inertial>
    <visual>
      <origin rpy="0 0 0" xyz="0 0 0"/>
      <geometry>
        <!--           <mesh filename="urdfs/iiwa14/meshes/visual/link_7.stl"/> -->
        <mesh filename="urdfs/iiwa14/meshes/visual/link_7-MF-Touch-pneumatisch.stl"/>
      </geometry>
      <material name="Grey"><color rgba="0.4 0.4 0.4 1.0"/></material>
    </visual>
    <collision>
      <origin rpy="0 0 0" xyz="0 0 0"/>
      <geometry>
        <!--           <mesh filename="urdfs/iiwa14/meshes/collision/link_7_s.stl"/> -->
        <mesh filename="urdfs/iiwa14/meshes/collision/link_7-MF-Touch-pneumatisch_s.stl"/>
      </geometry>
      <material name="Grey"><color rgba="0.4 0.4 0.4 1.0"/></material>
    </collision>
  </link>
  
  <joint name="joint_ee" type="fixed">
    <parent link="link_7"/>
    <child link="link_ee"/>
    <origin rpy="0 -1.5707963267948966 0" xyz="0 0 0.045"/>
  </joint>
  <link name="link_ee">
    </link>
  <joint name="joint_ee_kuka" type="fixed">
    <parent link="link_7"/>
    <child link="link_ee_kuka"/>
    <origin rpy="3.141592653589793 3.141592653589793 3.141592653589793" xyz="0 0 0.045"/>
    <axis xyz="0 0 1"/>
  </joint>
  <joint name="joint_ee_kuka_mft_pneum" type="fixed">
    <parent link="link_7"/>
    <child link="link_ee_kuka_mft_pneum"/>
    <origin rpy="0 -1.5707963267948966 0" xyz="0 0 0.071"/>
  </joint>
  <link name="link_ee_kuka">
    </link>
  <link name="link_ee_kuka_mft_pneum">
    </link>

</robot>
